<?xml version="1.0"?>
<!-- This URDF was automatically created by SolidWorks to URDF Exporter! Originally created by Stephen Brawner (brawner@gmail.com) 
     Commit Version: 1.6.0-4-g7f85cfe  Build Version: 1.6.7995.38578
     For more information, please see http://wiki.ros.org/sw_urdf_exporter -->
<robot
  name="AllPart_ROS_1">
  <link
    name="Origin_link">
    <inertial>
      <origin
        xyz="-0.0331747526357583 -0.00730194562036099 0.529403570251587"
        rpy="0 0 0" />
      <mass
        value="39.6499106151933" />
      <inertia
        ixx="1.97067595489131"
        ixy="0.128651653547729"
        ixz="0.00189639596414515"
        iyy="1.38397888622251"
        iyz="-0.000372030501518512"
        izz="1.27894920570797" />
    </inertial>
    <visual>
      <origin
        xyz="0 0 0"
        rpy="0 0 0" />
      <geometry>
        <mesh
          filename="package://AllPart_ROS_1/meshes/Origin_link.STL" />
      </geometry>
      <material
        name="">
        <color
          rgba="0.792156862745098 0.819607843137255 0.933333333333333 1" />
      </material>
    </visual>
    <collision>
      <origin
        xyz="0 0 0"
        rpy="0 0 0" />
      <geometry>
        <mesh
          filename="package://AllPart_ROS_1/meshes/Origin_link.STL" />
      </geometry>
    </collision>
  </link>
  <link
    name="Left_Wheel_Link">
    <inertial>
      <origin
        xyz="1.46040297392323E-15 -6.93889390390723E-18 0.00950000000000009"
        rpy="0 0 0" />
      <mass
        value="0.108269552981515" />
      <inertia
        ixx="9.25887924169887E-05"
        ixy="6.59159550628194E-22"
        ixz="-1.03456404054261E-23"
        iyy="9.25887924169888E-05"
        iyz="-1.41737744987348E-21"
        izz="0.000177381436372488" />
    </inertial>
    <visual>
      <origin
        xyz="0 0 0"
        rpy="0 0 0" />
      <geometry>
        <mesh
          filename="package://AllPart_ROS_1/meshes/Left_Wheel_Link.STL" />
      </geometry>
      <material
        name="">
        <color
          rgba="0.792156862745098 0.819607843137255 0.933333333333333 1" />
      </material>
    </visual>
    <collision>
      <origin
        xyz="0 0 0"
        rpy="0 0 0" />
      <geometry>
        <mesh
          filename="package://AllPart_ROS_1/meshes/Left_Wheel_Link.STL" />
      </geometry>
    </collision>
  </link>
  <joint
    name="wheel_Left"
    type="continuous">
    <origin
      xyz="0 0.133 -0.043"
      rpy="-1.5708 0 0" />
    <parent
      link="Origin_link" />
    <child
      link="Left_Wheel_Link" />
    <axis
      xyz="0 0 -1" />
  </joint>
  <link
    name="Right_Wheel_Link">
    <inertial>
      <origin
        xyz="-9.06056691907475E-17 0.000504197063261637 -0.00950000000000009"
        rpy="0 0 0" />
      <mass
        value="0.108269552981515" />
      <inertia
        ixx="9.25887924169887E-05"
        ixy="-6.00998413808059E-22"
        ixz="-2.5489630738247E-21"
        iyy="9.25887924169887E-05"
        iyz="-5.62673759504512E-21"
        izz="0.000177381436372488" />
    </inertial>
    <visual>
      <origin
        xyz="0 0 0"
        rpy="0 0 0" />
      <geometry>
        <mesh
          filename="package://AllPart_ROS_1/meshes/Right_Wheel_Link.STL" />
      </geometry>
      <material
        name="">
        <color
          rgba="0.792156862745098 0.819607843137255 0.933333333333333 1" />
      </material>
    </visual>
    <collision>
      <origin
        xyz="0 0 0"
        rpy="0 0 0" />
      <geometry>
        <mesh
          filename="package://AllPart_ROS_1/meshes/Right_Wheel_Link.STL" />
      </geometry>
    </collision>
  </link>
  <joint
    name="Wheel_Right"
    type="continuous">
    <origin
      xyz="0 -0.133 -0.042496"
      rpy="-1.5708 0 0" />
    <parent
      link="Origin_link" />
    <child
      link="Right_Wheel_Link" />
    <axis
      xyz="0 0 1" />
  </joint>
  <link
    name="Lidar_Front_Link">
    <inertial>
      <origin
        xyz="-2.34552673526456E-05 2.77555756156289E-17 -0.000925327978584606"
        rpy="0 0 0" />
      <mass
        value="0.248316720758954" />
      <inertia
        ixx="8.31868412025183E-05"
        ixy="-2.46791519512013E-17"
        ixz="1.59129766878296E-07"
        iyy="8.34263427877666E-05"
        iyz="4.6200741023068E-17"
        izz="0.000121555340807233" />
    </inertial>
    <visual>
      <origin
        xyz="0 0 0"
        rpy="0 0 0" />
      <geometry>
        <mesh
          filename="package://AllPart_ROS_1/meshes/Lidar_Front_Link.STL" />
      </geometry>
      <material
        name="">
        <color
          rgba="0.109803921568627 0.109803921568627 0.109803921568627 1" />
      </material>
    </visual>
    <collision>
      <origin
        xyz="0 0 0"
        rpy="0 0 0" />
      <geometry>
        <mesh
          filename="package://AllPart_ROS_1/meshes/Lidar_Front_Link.STL" />
      </geometry>
    </collision>
  </link>
  <joint
    name="Lidar_front"
    type="prismatic">
    <origin
      xyz="0.24 0.24 0.211"
      rpy="0 0 0.7854" />
    <parent
      link="Origin_link" />
    <child
      link="Lidar_Front_Link" />
    <axis
      xyz="0 0 -1" />
    <limit
      lower="0"
      upper="0"
      effort="0"
      velocity="0" />
  </joint>
  <link
    name="Lidar_Back_Link">
    <inertial>
      <origin
        xyz="-2.34552673528121E-05 -2.77555756156289E-17 -0.000925327978584661"
        rpy="0 0 0" />
      <mass
        value="0.248316720758954" />
      <inertia
        ixx="8.31868412025183E-05"
        ixy="-2.46994807419354E-17"
        ixz="1.59129766878286E-07"
        iyy="8.34263427877666E-05"
        iyz="4.62114039478004E-17"
        izz="0.000121555340807233" />
    </inertial>
    <visual>
      <origin
        xyz="0 0 0"
        rpy="0 0 0" />
      <geometry>
        <mesh
          filename="package://AllPart_ROS_1/meshes/Lidar_Back_Link.STL" />
      </geometry>
      <material
        name="">
        <color
          rgba="0.109803921568627 0.109803921568627 0.109803921568627 1" />
      </material>
    </visual>
    <collision>
      <origin
        xyz="0 0 0"
        rpy="0 0 0" />
      <geometry>
        <mesh
          filename="package://AllPart_ROS_1/meshes/Lidar_Back_Link.STL" />
      </geometry>
    </collision>
  </link>
  <joint
    name="Lidar_Back"
    type="prismatic">
    <origin
      xyz="-0.24 -0.24 0.211"
      rpy="0 0 -2.3562" />
    <parent
      link="Origin_link" />
    <child
      link="Lidar_Back_Link" />
    <axis
      xyz="0 0 -1" />
    <limit
      lower="0"
      upper="0"
      effort="0"
      velocity="0" />
  </joint>
  <link
    name="Cam_Front_Link">
    <inertial>
      <origin
        xyz="0.000136108231652887 -0.00348873421980028 -0.0124440208259819"
        rpy="0 0 0" />
      <mass
        value="0.107910427285575" />
      <inertia
        ixx="7.02567377723319E-05"
        ixy="-2.48245266666222E-10"
        ixz="-4.92978007946286E-08"
        iyy="7.71002128129138E-06"
        iyz="-1.78474723511188E-08"
        izz="7.12550269124943E-05" />
    </inertial>
    <visual>
      <origin
        xyz="0 0 0"
        rpy="0 0 0" />
      <geometry>
        <mesh
          filename="package://AllPart_ROS_1/meshes/Cam_Front_Link.STL" />
      </geometry>
      <material
        name="">
        <color
          rgba="0.898039215686275 0.917647058823529 0.929411764705882 1" />
      </material>
    </visual>
    <collision>
      <origin
        xyz="0 0 0"
        rpy="0 0 0" />
      <geometry>
        <mesh
          filename="package://AllPart_ROS_1/meshes/Cam_Front_Link.STL" />
      </geometry>
    </collision>
  </link>
  <joint
    name="Cam_Front"
    type="fixed">
    <origin
      xyz="0.26042 0.0035 0.27027"
      rpy="0 1.5708 0" />
    <parent
      link="Origin_link" />
    <child
      link="Cam_Front_Link" />
    <axis
      xyz="0 0 0" />
  </joint>
  <link
    name="Cam_Back_Link">
    <inertial>
      <origin
        xyz="0.000136108180038674 -0.003488733820115 -0.0124440209295308"
        rpy="0 0 0" />
      <mass
        value="0.107910426183708" />
      <inertia
        ixx="7.02567359597132E-05"
        ixy="-2.48455094253909E-10"
        ixz="-4.92977242763416E-08"
        iyy="7.71002115431573E-06"
        iyz="-1.7848010437949E-08"
        izz="7.12550253049952E-05" />
    </inertial>
    <visual>
      <origin
        xyz="0 0 0"
        rpy="0 0 0" />
      <geometry>
        <mesh
          filename="package://AllPart_ROS_1/meshes/Cam_Back_Link.STL" />
      </geometry>
      <material
        name="">
        <color
          rgba="0.898039215686275 0.917647058823529 0.929411764705882 1" />
      </material>
    </visual>
    <collision>
      <origin
        xyz="0 0 0"
        rpy="0 0 0" />
      <geometry>
        <mesh
          filename="package://AllPart_ROS_1/meshes/Cam_Back_Link.STL" />
      </geometry>
    </collision>
  </link>
  <joint
    name="Cam_Back"
    type="fixed">
    <origin
      xyz="-0.25742 -0.0035 0.31227"
      rpy="3.1416 1.5708 0" />
    <parent
      link="Origin_link" />
    <child
      link="Cam_Back_Link" />
    <axis
      xyz="0 0 0" />
  </joint>
  <link
    name="IMU_Link">
    <inertial>
      <origin
        xyz="0.00819747157258567 -0.000135591246461552 -8.58802587028196E-05"
        rpy="0 0 0" />
      <mass
        value="0.0178816032992711" />
      <inertia
        ixx="3.50890500832019E-06"
        ixy="5.90897838352298E-11"
        ixz="1.02803084562234E-08"
        iyy="1.96149528114783E-06"
        iyz="-2.2775473137505E-11"
        izz="2.25934528622389E-06" />
    </inertial>
    <visual>
      <origin
        xyz="0 0 0"
        rpy="0 0 0" />
      <geometry>
        <mesh
          filename="package://AllPart_ROS_1/meshes/IMU_Link.STL" />
      </geometry>
      <material
        name="">
        <color
          rgba="0.792156862745098 0.819607843137255 0.933333333333333 1" />
      </material>
    </visual>
    <collision>
      <origin
        xyz="0 0 0"
        rpy="0 0 0" />
      <geometry>
        <mesh
          filename="package://AllPart_ROS_1/meshes/IMU_Link.STL" />
      </geometry>
    </collision>
  </link>
  <joint
    name="IMU"
    type="fixed">
    <origin
      xyz="-0.124 0.00013601 0.46592"
      rpy="0 0 0" />
    <parent
      link="Origin_link" />
    <child
      link="IMU_Link" />
    <axis
      xyz="0 0 0" />
  </joint>
</robot>
